PS D:\FaceGuardNotify> flask db init
>> flask db migrate -m "Initial migration"
>> flask db upgrade
C:\Users\mithr\AppData\Roaming\Python\Python311\site-packages\flask_limiter\extension.py:364: UserWarning: Using the in-memory storage for tracking rate limits as no storage was explicitly specified. This is not recommended for production use. See: https://flask-limiter.readthedocs.io#configuring-a-storage-backend for documentation about configuring the storage backend.
  warnings.warn(
Traceback (most recent call last):
  File "C:\Users\mithr\AppData\Roaming\Python\Python311\site-packages\sqlalchemy\engine\base.py", line 143, in __init__
    self._dbapi_connection = engine.raw_connection()
                             ^^^^^^^^^^^^^^^^^^^^^^^
  File "C:\Users\mithr\AppData\Roaming\Python\Python311\site-packages\sqlalchemy\engine\base.py", line 3301, in raw_connection
    return self.pool.connect()
           ^^^^^^^^^^^^^^^^^^^
  File "C:\Users\mithr\AppData\Roaming\Python\Python311\site-packages\sqlalchemy\pool\base.py", line 447, in connect
    return _ConnectionFairy._checkout(self)
           ^^^^^^^^^^^^^^^^^^^^^^^^^^^^^^^^
  File "C:\Users\mithr\AppData\Roaming\Python\Python311\site-packages\sqlalchemy\pool\base.py", line 1264, in _checkout
    fairy = _ConnectionRecord.checkout(pool)
            ^^^^^^^^^^^^^^^^^^^^^^^^^^^^^^^^
  File "C:\Users\mithr\AppData\Roaming\Python\Python311\site-packages\sqlalchemy\pool\base.py", line 711, in checkout
    rec = pool._do_get()
          ^^^^^^^^^^^^^^
  File "C:\Users\mithr\AppData\Roaming\Python\Python311\site-packages\sqlalchemy\pool\impl.py", line 177, in _do_get
    with util.safe_reraise():
  File "C:\Users\mithr\AppData\Roaming\Python\Python311\site-packages\sqlalchemy\util\langhelpers.py", line 224, in __exit__
    raise exc_value.with_traceback(exc_tb)
  File "C:\Users\mithr\AppData\Roaming\Python\Python311\site-packages\sqlalchemy\pool\impl.py", line 175, in _do_get
    return self._create_connection()
           ^^^^^^^^^^^^^^^^^^^^^^^^^
  File "C:\Users\mithr\AppData\Roaming\Python\Python311\site-packages\sqlalchemy\pool\base.py", line 388, in _create_connection
    return _ConnectionRecord(self)
           ^^^^^^^^^^^^^^^^^^^^^^^
  File "C:\Users\mithr\AppData\Roaming\Python\Python311\site-packages\sqlalchemy\pool\base.py", line 673, in __init__
    self.__connect()
  File "C:\Users\mithr\AppData\Roaming\Python\Python311\site-packages\sqlalchemy\pool\base.py", line 899, in __connect
    with util.safe_reraise():
  File "C:\Users\mithr\AppData\Roaming\Python\Python311\site-packages\sqlalchemy\util\langhelpers.py", line 224, in __exit__
    raise exc_value.with_traceback(exc_tb)
  File "C:\Users\mithr\AppData\Roaming\Python\Python311\site-packages\sqlalchemy\pool\base.py", line 895, in __connect
    self.dbapi_connection = connection = pool._invoke_creator(self)
                                         ^^^^^^^^^^^^^^^^^^^^^^^^^^
  File "C:\Users\mithr\AppData\Roaming\Python\Python311\site-packages\sqlalchemy\engine\create.py", line 661, in connect
    return dialect.connect(*cargs, **cparams)
           ^^^^^^^^^^^^^^^^^^^^^^^^^^^^^^^^^^
  File "C:\Users\mithr\AppData\Roaming\Python\Python311\site-packages\sqlalchemy\engine\default.py", line 629, in connect
    return self.loaded_dbapi.connect(*cargs, **cparams)  # type: ignore[no-any-return]  # NOQA: E501
           ^^^^^^^^^^^^^^^^^^^^^^^^^^^^^^^^^^^^^^^^^^^^
  File "C:\Users\mithr\AppData\Roaming\Python\Python311\site-packages\psycopg2\__init__.py", line 122, in connect
    conn = _connect(dsn, connection_factory=connection_factory, **kwasync)
           ^^^^^^^^^^^^^^^^^^^^^^^^^^^^^^^^^^^^^^^^^^^^^^^^^^^^^^^^^^^^^^^
psycopg2.OperationalError: connection to server at "localhost" (::1), port 5432 failed: FATAL:  password authentication failed for user "root"


The above exception was the direct cause of the following exception:

Traceback (most recent call last):
  File "<frozen runpy>", line 198, in _run_module_as_main
  File "<frozen runpy>", line 88, in _run_code
  File "C:\Users\mithr\AppData\Roaming\Python\Python311\Scripts\flask.exe\__main__.py", line 6, in <module>
  File "C:\Users\mithr\AppData\Roaming\Python\Python311\site-packages\flask\cli.py", line 1131, in main
    cli.main()
  File "C:\Users\mithr\AppData\Roaming\Python\Python311\site-packages\click\core.py", line 1082, in main
    rv = self.invoke(ctx)
         ^^^^^^^^^^^^^^^^
  File "C:\Users\mithr\AppData\Roaming\Python\Python311\site-packages\click\core.py", line 1691, in invoke
    cmd_name, cmd, args = self.resolve_command(ctx, args)
                          ^^^^^^^^^^^^^^^^^^^^^^^^^^^^^^^
  File "C:\Users\mithr\AppData\Roaming\Python\Python311\site-packages\click\core.py", line 1738, in resolve_command
    cmd = self.get_command(ctx, cmd_name)
          ^^^^^^^^^^^^^^^^^^^^^^^^^^^^^^^
  File "C:\Users\mithr\AppData\Roaming\Python\Python311\site-packages\flask\cli.py", line 631, in get_command
    app = info.load_app()
          ^^^^^^^^^^^^^^^
  File "C:\Users\mithr\AppData\Roaming\Python\Python311\site-packages\flask\cli.py", line 353, in load_app
    app = locate_app(import_name, None, raise_if_not_found=False)
          ^^^^^^^^^^^^^^^^^^^^^^^^^^^^^^^^^^^^^^^^^^^^^^^^^^^^^^^
  File "C:\Users\mithr\AppData\Roaming\Python\Python311\site-packages\flask\cli.py", line 262, in locate_app
    return find_best_app(module)
           ^^^^^^^^^^^^^^^^^^^^^
  File "C:\Users\mithr\AppData\Roaming\Python\Python311\site-packages\flask\cli.py", line 72, in find_best_app
    app = app_factory()
          ^^^^^^^^^^^^^
  File "D:\FaceGuardNotify\app.py", line 100, in create_app
    db.create_all()
  File "C:\Users\mithr\AppData\Roaming\Python\Python311\site-packages\flask_sqlalchemy\extension.py", line 900, in create_all
    self._call_for_binds(bind_key, "create_all")
  File "C:\Users\mithr\AppData\Roaming\Python\Python311\site-packages\flask_sqlalchemy\extension.py", line 881, in _call_for_binds
    getattr(metadata, op_name)(bind=engine)
  File "C:\Users\mithr\AppData\Roaming\Python\Python311\site-packages\sqlalchemy\sql\schema.py", line 5924, in create_all
    bind._run_ddl_visitor(
  File "C:\Users\mithr\AppData\Roaming\Python\Python311\site-packages\sqlalchemy\engine\base.py", line 3251, in _run_ddl_visitor
    with self.begin() as conn:
  File "C:\Program Files\Python311\Lib\contextlib.py", line 137, in __enter__
    return next(self.gen)
           ^^^^^^^^^^^^^^
  File "C:\Users\mithr\AppData\Roaming\Python\Python311\site-packages\sqlalchemy\engine\base.py", line 3241, in begin
    with self.connect() as conn:
         ^^^^^^^^^^^^^^
  File "C:\Users\mithr\AppData\Roaming\Python\Python311\site-packages\sqlalchemy\engine\base.py", line 3277, in connect
    return self._connection_cls(self)
           ^^^^^^^^^^^^^^^^^^^^^^^^^^
  File "C:\Users\mithr\AppData\Roaming\Python\Python311\site-packages\sqlalchemy\engine\base.py", line 145, in __init__
    Connection._handle_dbapi_exception_noconnection(
  File "C:\Users\mithr\AppData\Roaming\Python\Python311\site-packages\sqlalchemy\engine\base.py", line 2440, in _handle_dbapi_exception_noconnection
    raise sqlalchemy_exception.with_traceback(exc_info[2]) from e
  File "C:\Users\mithr\AppData\Roaming\Python\Python311\site-packages\sqlalchemy\engine\base.py", line 143, in __init__
    self._dbapi_connection = engine.raw_connection()
                             ^^^^^^^^^^^^^^^^^^^^^^^
  File "C:\Users\mithr\AppData\Roaming\Python\Python311\site-packages\sqlalchemy\engine\base.py", line 3301, in raw_connection
    return self.pool.connect()
           ^^^^^^^^^^^^^^^^^^^
  File "C:\Users\mithr\AppData\Roaming\Python\Python311\site-packages\sqlalchemy\pool\base.py", line 447, in connect
    return _ConnectionFairy._checkout(self)
           ^^^^^^^^^^^^^^^^^^^^^^^^^^^^^^^^
  File "C:\Users\mithr\AppData\Roaming\Python\Python311\site-packages\sqlalchemy\pool\base.py", line 1264, in _checkout
    fairy = _ConnectionRecord.checkout(pool)
            ^^^^^^^^^^^^^^^^^^^^^^^^^^^^^^^^
  File "C:\Users\mithr\AppData\Roaming\Python\Python311\site-packages\sqlalchemy\pool\base.py", line 711, in checkout
    rec = pool._do_get()
          ^^^^^^^^^^^^^^
  File "C:\Users\mithr\AppData\Roaming\Python\Python311\site-packages\sqlalchemy\pool\impl.py", line 177, in _do_get
    with util.safe_reraise():
  File "C:\Users\mithr\AppData\Roaming\Python\Python311\site-packages\sqlalchemy\util\langhelpers.py", line 224, in __exit__
    raise exc_value.with_traceback(exc_tb)
  File "C:\Users\mithr\AppData\Roaming\Python\Python311\site-packages\sqlalchemy\pool\impl.py", line 175, in _do_get
    return self._create_connection()
           ^^^^^^^^^^^^^^^^^^^^^^^^^
  File "C:\Users\mithr\AppData\Roaming\Python\Python311\site-packages\sqlalchemy\pool\base.py", line 388, in _create_connection
    return _ConnectionRecord(self)
           ^^^^^^^^^^^^^^^^^^^^^^^
  File "C:\Users\mithr\AppData\Roaming\Python\Python311\site-packages\sqlalchemy\pool\base.py", line 673, in __init__
    self.__connect()
  File "C:\Users\mithr\AppData\Roaming\Python\Python311\site-packages\sqlalchemy\pool\base.py", line 899, in __connect
    with util.safe_reraise():
  File "C:\Users\mithr\AppData\Roaming\Python\Python311\site-packages\sqlalchemy\util\langhelpers.py", line 224, in __exit__
    raise exc_value.with_traceback(exc_tb)
  File "C:\Users\mithr\AppData\Roaming\Python\Python311\site-packages\sqlalchemy\pool\base.py", line 895, in __connect
    self.dbapi_connection = connection = pool._invoke_creator(self)
                                         ^^^^^^^^^^^^^^^^^^^^^^^^^^
  File "C:\Users\mithr\AppData\Roaming\Python\Python311\site-packages\sqlalchemy\engine\create.py", line 661, in connect
    return dialect.connect(*cargs, **cparams)
           ^^^^^^^^^^^^^^^^^^^^^^^^^^^^^^^^^^
  File "C:\Users\mithr\AppData\Roaming\Python\Python311\site-packages\sqlalchemy\engine\default.py", line 629, in connect
    return self.loaded_dbapi.connect(*cargs, **cparams)  # type: ignore[no-any-return]  # NOQA: E501
           ^^^^^^^^^^^^^^^^^^^^^^^^^^^^^^^^^^^^^^^^^^^^
  File "C:\Users\mithr\AppData\Roaming\Python\Python311\site-packages\psycopg2\__init__.py", line 122, in connect
    conn = _connect(dsn, connection_factory=connection_factory, **kwasync)
           ^^^^^^^^^^^^^^^^^^^^^^^^^^^^^^^^^^^^^^^^^^^^^^^^^^^^^^^^^^^^^^^
sqlalchemy.exc.OperationalError: (psycopg2.OperationalError) connection to server at "localhost" (::1), port 5432 failed: FATAL:  password authentication failed for user "root"

(Background on this error at: https://sqlalche.me/e/20/e3q8)
C:\Users\mithr\AppData\Roaming\Python\Python311\site-packages\flask_limiter\extension.py:364: UserWarning: Using the in-memory storage for tracking rate limits as no storage was explicitly specified. This is not recommended for production use. See: https://flask-limiter.readthedocs.io#configuring-a-storage-backend for documentation about configuring the storage backend.
  warnings.warn(
Traceback (most recent call last):
  File "C:\Users\mithr\AppData\Roaming\Python\Python311\site-packages\sqlalchemy\engine\base.py", line 143, in __init__
    self._dbapi_connection = engine.raw_connection()
                             ^^^^^^^^^^^^^^^^^^^^^^^
  File "C:\Users\mithr\AppData\Roaming\Python\Python311\site-packages\sqlalchemy\engine\base.py", line 3301, in raw_connection
    return self.pool.connect()
           ^^^^^^^^^^^^^^^^^^^
  File "C:\Users\mithr\AppData\Roaming\Python\Python311\site-packages\sqlalchemy\pool\base.py", line 447, in connect
    return _ConnectionFairy._checkout(self)
           ^^^^^^^^^^^^^^^^^^^^^^^^^^^^^^^^
  File "C:\Users\mithr\AppData\Roaming\Python\Python311\site-packages\sqlalchemy\pool\base.py", line 1264, in _checkout
    fairy = _ConnectionRecord.checkout(pool)
            ^^^^^^^^^^^^^^^^^^^^^^^^^^^^^^^^
  File "C:\Users\mithr\AppData\Roaming\Python\Python311\site-packages\sqlalchemy\pool\base.py", line 711, in checkout
    rec = pool._do_get()
          ^^^^^^^^^^^^^^
  File "C:\Users\mithr\AppData\Roaming\Python\Python311\site-packages\sqlalchemy\pool\impl.py", line 177, in _do_get
    with util.safe_reraise():
  File "C:\Users\mithr\AppData\Roaming\Python\Python311\site-packages\sqlalchemy\util\langhelpers.py", line 224, in __exit__
    raise exc_value.with_traceback(exc_tb)
  File "C:\Users\mithr\AppData\Roaming\Python\Python311\site-packages\sqlalchemy\pool\impl.py", line 175, in _do_get
    return self._create_connection()
           ^^^^^^^^^^^^^^^^^^^^^^^^^
  File "C:\Users\mithr\AppData\Roaming\Python\Python311\site-packages\sqlalchemy\pool\base.py", line 388, in _create_connection
    return _ConnectionRecord(self)
           ^^^^^^^^^^^^^^^^^^^^^^^
  File "C:\Users\mithr\AppData\Roaming\Python\Python311\site-packages\sqlalchemy\pool\base.py", line 673, in __init__
    self.__connect()
  File "C:\Users\mithr\AppData\Roaming\Python\Python311\site-packages\sqlalchemy\pool\base.py", line 899, in __connect
    with util.safe_reraise():
  File "C:\Users\mithr\AppData\Roaming\Python\Python311\site-packages\sqlalchemy\util\langhelpers.py", line 224, in __exit__
    raise exc_value.with_traceback(exc_tb)
  File "C:\Users\mithr\AppData\Roaming\Python\Python311\site-packages\sqlalchemy\pool\base.py", line 895, in __connect
    self.dbapi_connection = connection = pool._invoke_creator(self)
                                         ^^^^^^^^^^^^^^^^^^^^^^^^^^
  File "C:\Users\mithr\AppData\Roaming\Python\Python311\site-packages\sqlalchemy\engine\create.py", line 661, in connect
    return dialect.connect(*cargs, **cparams)
           ^^^^^^^^^^^^^^^^^^^^^^^^^^^^^^^^^^
  File "C:\Users\mithr\AppData\Roaming\Python\Python311\site-packages\sqlalchemy\engine\default.py", line 629, in connect
    return self.loaded_dbapi.connect(*cargs, **cparams)  # type: ignore[no-any-return]  # NOQA: E501
           ^^^^^^^^^^^^^^^^^^^^^^^^^^^^^^^^^^^^^^^^^^^^
  File "C:\Users\mithr\AppData\Roaming\Python\Python311\site-packages\psycopg2\__init__.py", line 122, in connect
    conn = _connect(dsn, connection_factory=connection_factory, **kwasync)
           ^^^^^^^^^^^^^^^^^^^^^^^^^^^^^^^^^^^^^^^^^^^^^^^^^^^^^^^^^^^^^^^
psycopg2.OperationalError: connection to server at "localhost" (::1), port 5432 failed: FATAL:  password authentication failed for user "root"


The above exception was the direct cause of the following exception:

Traceback (most recent call last):
  File "<frozen runpy>", line 198, in _run_module_as_main
  File "<frozen runpy>", line 88, in _run_code
  File "C:\Users\mithr\AppData\Roaming\Python\Python311\Scripts\flask.exe\__main__.py", line 6, in <module>
  File "C:\Users\mithr\AppData\Roaming\Python\Python311\site-packages\flask\cli.py", line 1131, in main
    cli.main()
  File "C:\Users\mithr\AppData\Roaming\Python\Python311\site-packages\click\core.py", line 1082, in main
    rv = self.invoke(ctx)
         ^^^^^^^^^^^^^^^^
  File "C:\Users\mithr\AppData\Roaming\Python\Python311\site-packages\click\core.py", line 1691, in invoke
    cmd_name, cmd, args = self.resolve_command(ctx, args)
                          ^^^^^^^^^^^^^^^^^^^^^^^^^^^^^^^
  File "C:\Users\mithr\AppData\Roaming\Python\Python311\site-packages\click\core.py", line 1738, in resolve_command
    cmd = self.get_command(ctx, cmd_name)
          ^^^^^^^^^^^^^^^^^^^^^^^^^^^^^^^
  File "C:\Users\mithr\AppData\Roaming\Python\Python311\site-packages\flask\cli.py", line 631, in get_command
    app = info.load_app()
          ^^^^^^^^^^^^^^^
  File "C:\Users\mithr\AppData\Roaming\Python\Python311\site-packages\flask\cli.py", line 353, in load_app
    app = locate_app(import_name, None, raise_if_not_found=False)
          ^^^^^^^^^^^^^^^^^^^^^^^^^^^^^^^^^^^^^^^^^^^^^^^^^^^^^^^
  File "C:\Users\mithr\AppData\Roaming\Python\Python311\site-packages\flask\cli.py", line 262, in locate_app
    return find_best_app(module)
           ^^^^^^^^^^^^^^^^^^^^^
  File "C:\Users\mithr\AppData\Roaming\Python\Python311\site-packages\flask\cli.py", line 72, in find_best_app
    app = app_factory()
          ^^^^^^^^^^^^^
  File "D:\FaceGuardNotify\app.py", line 100, in create_app
    db.create_all()
  File "C:\Users\mithr\AppData\Roaming\Python\Python311\site-packages\flask_sqlalchemy\extension.py", line 900, in create_all
    self._call_for_binds(bind_key, "create_all")
  File "C:\Users\mithr\AppData\Roaming\Python\Python311\site-packages\flask_sqlalchemy\extension.py", line 881, in _call_for_binds
    getattr(metadata, op_name)(bind=engine)
  File "C:\Users\mithr\AppData\Roaming\Python\Python311\site-packages\sqlalchemy\sql\schema.py", line 5924, in create_all
    bind._run_ddl_visitor(
  File "C:\Users\mithr\AppData\Roaming\Python\Python311\site-packages\sqlalchemy\engine\base.py", line 3251, in _run_ddl_visitor
    with self.begin() as conn:
  File "C:\Program Files\Python311\Lib\contextlib.py", line 137, in __enter__
    return next(self.gen)
           ^^^^^^^^^^^^^^
  File "C:\Users\mithr\AppData\Roaming\Python\Python311\site-packages\sqlalchemy\engine\base.py", line 3241, in begin
    with self.connect() as conn:
         ^^^^^^^^^^^^^^
  File "C:\Users\mithr\AppData\Roaming\Python\Python311\site-packages\sqlalchemy\engine\base.py", line 3277, in connect
    return self._connection_cls(self)
           ^^^^^^^^^^^^^^^^^^^^^^^^^^
  File "C:\Users\mithr\AppData\Roaming\Python\Python311\site-packages\sqlalchemy\engine\base.py", line 145, in __init__
    Connection._handle_dbapi_exception_noconnection(
  File "C:\Users\mithr\AppData\Roaming\Python\Python311\site-packages\sqlalchemy\engine\base.py", line 2440, in _handle_dbapi_exception_noconnection
    raise sqlalchemy_exception.with_traceback(exc_info[2]) from e
  File "C:\Users\mithr\AppData\Roaming\Python\Python311\site-packages\sqlalchemy\engine\base.py", line 143, in __init__
    self._dbapi_connection = engine.raw_connection()
                             ^^^^^^^^^^^^^^^^^^^^^^^
  File "C:\Users\mithr\AppData\Roaming\Python\Python311\site-packages\sqlalchemy\engine\base.py", line 3301, in raw_connection
    return self.pool.connect()
           ^^^^^^^^^^^^^^^^^^^
  File "C:\Users\mithr\AppData\Roaming\Python\Python311\site-packages\sqlalchemy\pool\base.py", line 447, in connect
    return _ConnectionFairy._checkout(self)
           ^^^^^^^^^^^^^^^^^^^^^^^^^^^^^^^^
  File "C:\Users\mithr\AppData\Roaming\Python\Python311\site-packages\sqlalchemy\pool\base.py", line 1264, in _checkout
    fairy = _ConnectionRecord.checkout(pool)
            ^^^^^^^^^^^^^^^^^^^^^^^^^^^^^^^^
  File "C:\Users\mithr\AppData\Roaming\Python\Python311\site-packages\sqlalchemy\pool\base.py", line 711, in checkout
    rec = pool._do_get()
          ^^^^^^^^^^^^^^
  File "C:\Users\mithr\AppData\Roaming\Python\Python311\site-packages\sqlalchemy\pool\impl.py", line 177, in _do_get
    with util.safe_reraise():
  File "C:\Users\mithr\AppData\Roaming\Python\Python311\site-packages\sqlalchemy\util\langhelpers.py", line 224, in __exit__
    raise exc_value.with_traceback(exc_tb)
  File "C:\Users\mithr\AppData\Roaming\Python\Python311\site-packages\sqlalchemy\pool\impl.py", line 175, in _do_get
    return self._create_connection()
           ^^^^^^^^^^^^^^^^^^^^^^^^^
  File "C:\Users\mithr\AppData\Roaming\Python\Python311\site-packages\sqlalchemy\pool\base.py", line 388, in _create_connection
    return _ConnectionRecord(self)
           ^^^^^^^^^^^^^^^^^^^^^^^
  File "C:\Users\mithr\AppData\Roaming\Python\Python311\site-packages\sqlalchemy\pool\base.py", line 673, in __init__
    self.__connect()
  File "C:\Users\mithr\AppData\Roaming\Python\Python311\site-packages\sqlalchemy\pool\base.py", line 899, in __connect
    with util.safe_reraise():
  File "C:\Users\mithr\AppData\Roaming\Python\Python311\site-packages\sqlalchemy\util\langhelpers.py", line 224, in __exit__
    raise exc_value.with_traceback(exc_tb)
  File "C:\Users\mithr\AppData\Roaming\Python\Python311\site-packages\sqlalchemy\pool\base.py", line 895, in __connect
    self.dbapi_connection = connection = pool._invoke_creator(self)
                                         ^^^^^^^^^^^^^^^^^^^^^^^^^^
  File "C:\Users\mithr\AppData\Roaming\Python\Python311\site-packages\sqlalchemy\engine\create.py", line 661, in connect
    return dialect.connect(*cargs, **cparams)
           ^^^^^^^^^^^^^^^^^^^^^^^^^^^^^^^^^^
  File "C:\Users\mithr\AppData\Roaming\Python\Python311\site-packages\sqlalchemy\engine\default.py", line 629, in connect
    return self.loaded_dbapi.connect(*cargs, **cparams)  # type: ignore[no-any-return]  # NOQA: E501
           ^^^^^^^^^^^^^^^^^^^^^^^^^^^^^^^^^^^^^^^^^^^^
  File "C:\Users\mithr\AppData\Roaming\Python\Python311\site-packages\psycopg2\__init__.py", line 122, in connect
    conn = _connect(dsn, connection_factory=connection_factory, **kwasync)
           ^^^^^^^^^^^^^^^^^^^^^^^^^^^^^^^^^^^^^^^^^^^^^^^^^^^^^^^^^^^^^^^
sqlalchemy.exc.OperationalError: (psycopg2.OperationalError) connection to server at "localhost" (::1), port 5432 failed: FATAL:  password authentication failed for user "root"

(Background on this error at: https://sqlalche.me/e/20/e3q8)
C:\Users\mithr\AppData\Roaming\Python\Python311\site-packages\flask_limiter\extension.py:364: UserWarning: Using the in-memory storage for tracking rate limits as no storage was explicitly specified. This is not recommended for production use. See: https://flask-limiter.readthedocs.io#configuring-a-storage-backend for documentation about configuring the storage backend.
  warnings.warn(
Traceback (most recent call last):
  File "C:\Users\mithr\AppData\Roaming\Python\Python311\site-packages\sqlalchemy\engine\base.py", line 143, in __init__
    self._dbapi_connection = engine.raw_connection()
                             ^^^^^^^^^^^^^^^^^^^^^^^
  File "C:\Users\mithr\AppData\Roaming\Python\Python311\site-packages\sqlalchemy\engine\base.py", line 3301, in raw_connection
    return self.pool.connect()
           ^^^^^^^^^^^^^^^^^^^
  File "C:\Users\mithr\AppData\Roaming\Python\Python311\site-packages\sqlalchemy\pool\base.py", line 447, in connect
    return _ConnectionFairy._checkout(self)
           ^^^^^^^^^^^^^^^^^^^^^^^^^^^^^^^^
  File "C:\Users\mithr\AppData\Roaming\Python\Python311\site-packages\sqlalchemy\pool\base.py", line 1264, in _checkout
    fairy = _ConnectionRecord.checkout(pool)
            ^^^^^^^^^^^^^^^^^^^^^^^^^^^^^^^^
  File "C:\Users\mithr\AppData\Roaming\Python\Python311\site-packages\sqlalchemy\pool\base.py", line 711, in checkout
    rec = pool._do_get()
          ^^^^^^^^^^^^^^
  File "C:\Users\mithr\AppData\Roaming\Python\Python311\site-packages\sqlalchemy\pool\impl.py", line 177, in _do_get
    with util.safe_reraise():
  File "C:\Users\mithr\AppData\Roaming\Python\Python311\site-packages\sqlalchemy\util\langhelpers.py", line 224, in __exit__
    raise exc_value.with_traceback(exc_tb)
  File "C:\Users\mithr\AppData\Roaming\Python\Python311\site-packages\sqlalchemy\pool\impl.py", line 175, in _do_get
    return self._create_connection()
           ^^^^^^^^^^^^^^^^^^^^^^^^^
  File "C:\Users\mithr\AppData\Roaming\Python\Python311\site-packages\sqlalchemy\pool\base.py", line 388, in _create_connection
    return _ConnectionRecord(self)
           ^^^^^^^^^^^^^^^^^^^^^^^
  File "C:\Users\mithr\AppData\Roaming\Python\Python311\site-packages\sqlalchemy\pool\base.py", line 673, in __init__
    self.__connect()
  File "C:\Users\mithr\AppData\Roaming\Python\Python311\site-packages\sqlalchemy\pool\base.py", line 899, in __connect
    with util.safe_reraise():
  File "C:\Users\mithr\AppData\Roaming\Python\Python311\site-packages\sqlalchemy\util\langhelpers.py", line 224, in __exit__
    raise exc_value.with_traceback(exc_tb)
  File "C:\Users\mithr\AppData\Roaming\Python\Python311\site-packages\sqlalchemy\pool\base.py", line 895, in __connect
    self.dbapi_connection = connection = pool._invoke_creator(self)
                                         ^^^^^^^^^^^^^^^^^^^^^^^^^^
  File "C:\Users\mithr\AppData\Roaming\Python\Python311\site-packages\sqlalchemy\engine\create.py", line 661, in connect
    return dialect.connect(*cargs, **cparams)
           ^^^^^^^^^^^^^^^^^^^^^^^^^^^^^^^^^^
  File "C:\Users\mithr\AppData\Roaming\Python\Python311\site-packages\sqlalchemy\engine\default.py", line 629, in connect
    return self.loaded_dbapi.connect(*cargs, **cparams)  # type: ignore[no-any-return]  # NOQA: E501
           ^^^^^^^^^^^^^^^^^^^^^^^^^^^^^^^^^^^^^^^^^^^^
  File "C:\Users\mithr\AppData\Roaming\Python\Python311\site-packages\psycopg2\__init__.py", line 122, in connect
    conn = _connect(dsn, connection_factory=connection_factory, **kwasync)
           ^^^^^^^^^^^^^^^^^^^^^^^^^^^^^^^^^^^^^^^^^^^^^^^^^^^^^^^^^^^^^^^
psycopg2.OperationalError: connection to server at "localhost" (::1), port 5432 failed: FATAL:  password authentication failed for user "root"


The above exception was the direct cause of the following exception:

Traceback (most recent call last):
  File "<frozen runpy>", line 198, in _run_module_as_main
  File "<frozen runpy>", line 88, in _run_code
  File "C:\Users\mithr\AppData\Roaming\Python\Python311\Scripts\flask.exe\__main__.py", line 6, in <module>
  File "C:\Users\mithr\AppData\Roaming\Python\Python311\site-packages\flask\cli.py", line 1131, in main
    cli.main()
  File "C:\Users\mithr\AppData\Roaming\Python\Python311\site-packages\click\core.py", line 1082, in main
    rv = self.invoke(ctx)
         ^^^^^^^^^^^^^^^^
  File "C:\Users\mithr\AppData\Roaming\Python\Python311\site-packages\click\core.py", line 1691, in invoke
    cmd_name, cmd, args = self.resolve_command(ctx, args)
                          ^^^^^^^^^^^^^^^^^^^^^^^^^^^^^^^
  File "C:\Users\mithr\AppData\Roaming\Python\Python311\site-packages\click\core.py", line 1738, in resolve_command
    cmd = self.get_command(ctx, cmd_name)
          ^^^^^^^^^^^^^^^^^^^^^^^^^^^^^^^
  File "C:\Users\mithr\AppData\Roaming\Python\Python311\site-packages\flask\cli.py", line 631, in get_command
    app = info.load_app()
          ^^^^^^^^^^^^^^^
  File "C:\Users\mithr\AppData\Roaming\Python\Python311\site-packages\flask\cli.py", line 353, in load_app
    app = locate_app(import_name, None, raise_if_not_found=False)
          ^^^^^^^^^^^^^^^^^^^^^^^^^^^^^^^^^^^^^^^^^^^^^^^^^^^^^^^
  File "C:\Users\mithr\AppData\Roaming\Python\Python311\site-packages\flask\cli.py", line 262, in locate_app
    return find_best_app(module)
           ^^^^^^^^^^^^^^^^^^^^^
  File "C:\Users\mithr\AppData\Roaming\Python\Python311\site-packages\flask\cli.py", line 72, in find_best_app
    app = app_factory()
          ^^^^^^^^^^^^^
  File "D:\FaceGuardNotify\app.py", line 100, in create_app
    db.create_all()
  File "C:\Users\mithr\AppData\Roaming\Python\Python311\site-packages\flask_sqlalchemy\extension.py", line 900, in create_all
    self._call_for_binds(bind_key, "create_all")
  File "C:\Users\mithr\AppData\Roaming\Python\Python311\site-packages\flask_sqlalchemy\extension.py", line 881, in _call_for_binds
    getattr(metadata, op_name)(bind=engine)
  File "C:\Users\mithr\AppData\Roaming\Python\Python311\site-packages\sqlalchemy\sql\schema.py", line 5924, in create_all
    bind._run_ddl_visitor(
  File "C:\Users\mithr\AppData\Roaming\Python\Python311\site-packages\sqlalchemy\engine\base.py", line 3251, in _run_ddl_visitor
    with self.begin() as conn:
  File "C:\Program Files\Python311\Lib\contextlib.py", line 137, in __enter__
    return next(self.gen)
           ^^^^^^^^^^^^^^
  File "C:\Users\mithr\AppData\Roaming\Python\Python311\site-packages\sqlalchemy\engine\base.py", line 3241, in begin
    with self.connect() as conn:
         ^^^^^^^^^^^^^^
  File "C:\Users\mithr\AppData\Roaming\Python\Python311\site-packages\sqlalchemy\engine\base.py", line 3277, in connect
    return self._connection_cls(self)
           ^^^^^^^^^^^^^^^^^^^^^^^^^^
  File "C:\Users\mithr\AppData\Roaming\Python\Python311\site-packages\sqlalchemy\engine\base.py", line 145, in __init__
    Connection._handle_dbapi_exception_noconnection(
  File "C:\Users\mithr\AppData\Roaming\Python\Python311\site-packages\sqlalchemy\engine\base.py", line 2440, in _handle_dbapi_exception_noconnection
    raise sqlalchemy_exception.with_traceback(exc_info[2]) from e
  File "C:\Users\mithr\AppData\Roaming\Python\Python311\site-packages\sqlalchemy\engine\base.py", line 143, in __init__
    self._dbapi_connection = engine.raw_connection()
                             ^^^^^^^^^^^^^^^^^^^^^^^
  File "C:\Users\mithr\AppData\Roaming\Python\Python311\site-packages\sqlalchemy\engine\base.py", line 3301, in raw_connection
    return self.pool.connect()
           ^^^^^^^^^^^^^^^^^^^
  File "C:\Users\mithr\AppData\Roaming\Python\Python311\site-packages\sqlalchemy\pool\base.py", line 447, in connect
    return _ConnectionFairy._checkout(self)
           ^^^^^^^^^^^^^^^^^^^^^^^^^^^^^^^^
  File "C:\Users\mithr\AppData\Roaming\Python\Python311\site-packages\sqlalchemy\pool\base.py", line 1264, in _checkout
    fairy = _ConnectionRecord.checkout(pool)
            ^^^^^^^^^^^^^^^^^^^^^^^^^^^^^^^^
  File "C:\Users\mithr\AppData\Roaming\Python\Python311\site-packages\sqlalchemy\pool\base.py", line 711, in checkout
    rec = pool._do_get()
          ^^^^^^^^^^^^^^
  File "C:\Users\mithr\AppData\Roaming\Python\Python311\site-packages\sqlalchemy\pool\impl.py", line 177, in _do_get
    with util.safe_reraise():
  File "C:\Users\mithr\AppData\Roaming\Python\Python311\site-packages\sqlalchemy\util\langhelpers.py", line 224, in __exit__
    raise exc_value.with_traceback(exc_tb)
  File "C:\Users\mithr\AppData\Roaming\Python\Python311\site-packages\sqlalchemy\pool\impl.py", line 175, in _do_get
    return self._create_connection()
           ^^^^^^^^^^^^^^^^^^^^^^^^^
  File "C:\Users\mithr\AppData\Roaming\Python\Python311\site-packages\sqlalchemy\pool\base.py", line 388, in _create_connection
    return _ConnectionRecord(self)
           ^^^^^^^^^^^^^^^^^^^^^^^
  File "C:\Users\mithr\AppData\Roaming\Python\Python311\site-packages\sqlalchemy\pool\base.py", line 673, in __init__
    self.__connect()
  File "C:\Users\mithr\AppData\Roaming\Python\Python311\site-packages\sqlalchemy\pool\base.py", line 899, in __connect
    with util.safe_reraise():
  File "C:\Users\mithr\AppData\Roaming\Python\Python311\site-packages\sqlalchemy\util\langhelpers.py", line 224, in __exit__
    raise exc_value.with_traceback(exc_tb)
  File "C:\Users\mithr\AppData\Roaming\Python\Python311\site-packages\sqlalchemy\pool\base.py", line 895, in __connect
    self.dbapi_connection = connection = pool._invoke_creator(self)
                                         ^^^^^^^^^^^^^^^^^^^^^^^^^^
  File "C:\Users\mithr\AppData\Roaming\Python\Python311\site-packages\sqlalchemy\engine\create.py", line 661, in connect
    return dialect.connect(*cargs, **cparams)
           ^^^^^^^^^^^^^^^^^^^^^^^^^^^^^^^^^^
  File "C:\Users\mithr\AppData\Roaming\Python\Python311\site-packages\sqlalchemy\engine\default.py", line 629, in connect
    return self.loaded_dbapi.connect(*cargs, **cparams)  # type: ignore[no-any-return]  # NOQA: E501
           ^^^^^^^^^^^^^^^^^^^^^^^^^^^^^^^^^^^^^^^^^^^^
  File "C:\Users\mithr\AppData\Roaming\Python\Python311\site-packages\psycopg2\__init__.py", line 122, in connect
    conn = _connect(dsn, connection_factory=connection_factory, **kwasync)
           ^^^^^^^^^^^^^^^^^^^^^^^^^^^^^^^^^^^^^^^^^^^^^^^^^^^^^^^^^^^^^^^
sqlalchemy.exc.OperationalError: (psycopg2.OperationalError) connection to server at "localhost" (::1), port 5432 failed: FATAL:  password authentication failed for user "root"

(Background on this error at: https://sqlalche.me/e/20/e3q8)
PS D:\FaceGuardNotify> 